2024-04-15 22:53:12,137 ERROR |  390 start_polling: Cause exception while getting updates.
Traceback (most recent call last):
  File "C:\Users\angel\AppData\Local\Programs\Python\Python39\lib\site-packages\aiogram\dispatcher\dispatcher.py", line 381, in start_polling
    updates = await self.bot.get_updates(
  File "C:\Users\angel\AppData\Local\Programs\Python\Python39\lib\site-packages\aiogram\bot\bot.py", line 110, in get_updates
    result = await self.request(api.Methods.GET_UPDATES, payload)
  File "C:\Users\angel\AppData\Local\Programs\Python\Python39\lib\site-packages\aiogram\bot\base.py", line 236, in request
    return await api.make_request(await self.get_session(), self.server, self.__token, method, data, files,
  File "C:\Users\angel\AppData\Local\Programs\Python\Python39\lib\site-packages\aiogram\bot\api.py", line 140, in make_request
    return check_result(method, response.content_type, response.status, await response.text())
  File "C:\Users\angel\AppData\Local\Programs\Python\Python39\lib\site-packages\aiogram\bot\api.py", line 119, in check_result
    exceptions.ConflictError.detect(description)
  File "C:\Users\angel\AppData\Local\Programs\Python\Python39\lib\site-packages\aiogram\utils\exceptions.py", line 140, in detect
    raise err(cls.text or description)
aiogram.utils.exceptions.TerminatedByOtherGetUpdates: Terminated by other getupdates request; make sure that only one bot instance is running
2024-04-15 22:53:22,284 ERROR |  390 start_polling: Cause exception while getting updates.
Traceback (most recent call last):
  File "C:\Users\angel\AppData\Local\Programs\Python\Python39\lib\site-packages\aiogram\dispatcher\dispatcher.py", line 381, in start_polling
    updates = await self.bot.get_updates(
  File "C:\Users\angel\AppData\Local\Programs\Python\Python39\lib\site-packages\aiogram\bot\bot.py", line 110, in get_updates
    result = await self.request(api.Methods.GET_UPDATES, payload)
  File "C:\Users\angel\AppData\Local\Programs\Python\Python39\lib\site-packages\aiogram\bot\base.py", line 236, in request
    return await api.make_request(await self.get_session(), self.server, self.__token, method, data, files,
  File "C:\Users\angel\AppData\Local\Programs\Python\Python39\lib\site-packages\aiogram\bot\api.py", line 140, in make_request
    return check_result(method, response.content_type, response.status, await response.text())
  File "C:\Users\angel\AppData\Local\Programs\Python\Python39\lib\site-packages\aiogram\bot\api.py", line 119, in check_result
    exceptions.ConflictError.detect(description)
  File "C:\Users\angel\AppData\Local\Programs\Python\Python39\lib\site-packages\aiogram\utils\exceptions.py", line 140, in detect
    raise err(cls.text or description)
aiogram.utils.exceptions.TerminatedByOtherGetUpdates: Terminated by other getupdates request; make sure that only one bot instance is running
2024-04-15 22:53:32,440 ERROR |  390 start_polling: Cause exception while getting updates.
Traceback (most recent call last):
  File "C:\Users\angel\AppData\Local\Programs\Python\Python39\lib\site-packages\aiogram\dispatcher\dispatcher.py", line 381, in start_polling
    updates = await self.bot.get_updates(
  File "C:\Users\angel\AppData\Local\Programs\Python\Python39\lib\site-packages\aiogram\bot\bot.py", line 110, in get_updates
    result = await self.request(api.Methods.GET_UPDATES, payload)
  File "C:\Users\angel\AppData\Local\Programs\Python\Python39\lib\site-packages\aiogram\bot\base.py", line 236, in request
    return await api.make_request(await self.get_session(), self.server, self.__token, method, data, files,
  File "C:\Users\angel\AppData\Local\Programs\Python\Python39\lib\site-packages\aiogram\bot\api.py", line 140, in make_request
    return check_result(method, response.content_type, response.status, await response.text())
  File "C:\Users\angel\AppData\Local\Programs\Python\Python39\lib\site-packages\aiogram\bot\api.py", line 119, in check_result
    exceptions.ConflictError.detect(description)
  File "C:\Users\angel\AppData\Local\Programs\Python\Python39\lib\site-packages\aiogram\utils\exceptions.py", line 140, in detect
    raise err(cls.text or description)
aiogram.utils.exceptions.TerminatedByOtherGetUpdates: Terminated by other getupdates request; make sure that only one bot instance is running
2024-04-15 22:53:42,594 ERROR |  390 start_polling: Cause exception while getting updates.
Traceback (most recent call last):
  File "C:\Users\angel\AppData\Local\Programs\Python\Python39\lib\site-packages\aiogram\dispatcher\dispatcher.py", line 381, in start_polling
    updates = await self.bot.get_updates(
  File "C:\Users\angel\AppData\Local\Programs\Python\Python39\lib\site-packages\aiogram\bot\bot.py", line 110, in get_updates
    result = await self.request(api.Methods.GET_UPDATES, payload)
  File "C:\Users\angel\AppData\Local\Programs\Python\Python39\lib\site-packages\aiogram\bot\base.py", line 236, in request
    return await api.make_request(await self.get_session(), self.server, self.__token, method, data, files,
  File "C:\Users\angel\AppData\Local\Programs\Python\Python39\lib\site-packages\aiogram\bot\api.py", line 140, in make_request
    return check_result(method, response.content_type, response.status, await response.text())
  File "C:\Users\angel\AppData\Local\Programs\Python\Python39\lib\site-packages\aiogram\bot\api.py", line 119, in check_result
    exceptions.ConflictError.detect(description)
  File "C:\Users\angel\AppData\Local\Programs\Python\Python39\lib\site-packages\aiogram\utils\exceptions.py", line 140, in detect
    raise err(cls.text or description)
aiogram.utils.exceptions.TerminatedByOtherGetUpdates: Terminated by other getupdates request; make sure that only one bot instance is running
2024-04-15 22:53:52,726 ERROR |  390 start_polling: Cause exception while getting updates.
Traceback (most recent call last):
  File "C:\Users\angel\AppData\Local\Programs\Python\Python39\lib\site-packages\aiogram\dispatcher\dispatcher.py", line 381, in start_polling
    updates = await self.bot.get_updates(
  File "C:\Users\angel\AppData\Local\Programs\Python\Python39\lib\site-packages\aiogram\bot\bot.py", line 110, in get_updates
    result = await self.request(api.Methods.GET_UPDATES, payload)
  File "C:\Users\angel\AppData\Local\Programs\Python\Python39\lib\site-packages\aiogram\bot\base.py", line 236, in request
    return await api.make_request(await self.get_session(), self.server, self.__token, method, data, files,
  File "C:\Users\angel\AppData\Local\Programs\Python\Python39\lib\site-packages\aiogram\bot\api.py", line 140, in make_request
    return check_result(method, response.content_type, response.status, await response.text())
  File "C:\Users\angel\AppData\Local\Programs\Python\Python39\lib\site-packages\aiogram\bot\api.py", line 119, in check_result
    exceptions.ConflictError.detect(description)
  File "C:\Users\angel\AppData\Local\Programs\Python\Python39\lib\site-packages\aiogram\utils\exceptions.py", line 140, in detect
    raise err(cls.text or description)
aiogram.utils.exceptions.TerminatedByOtherGetUpdates: Terminated by other getupdates request; make sure that only one bot instance is running
2024-04-15 22:54:02,861 ERROR |  390 start_polling: Cause exception while getting updates.
Traceback (most recent call last):
  File "C:\Users\angel\AppData\Local\Programs\Python\Python39\lib\site-packages\aiogram\dispatcher\dispatcher.py", line 381, in start_polling
    updates = await self.bot.get_updates(
  File "C:\Users\angel\AppData\Local\Programs\Python\Python39\lib\site-packages\aiogram\bot\bot.py", line 110, in get_updates
    result = await self.request(api.Methods.GET_UPDATES, payload)
  File "C:\Users\angel\AppData\Local\Programs\Python\Python39\lib\site-packages\aiogram\bot\base.py", line 236, in request
    return await api.make_request(await self.get_session(), self.server, self.__token, method, data, files,
  File "C:\Users\angel\AppData\Local\Programs\Python\Python39\lib\site-packages\aiogram\bot\api.py", line 140, in make_request
    return check_result(method, response.content_type, response.status, await response.text())
  File "C:\Users\angel\AppData\Local\Programs\Python\Python39\lib\site-packages\aiogram\bot\api.py", line 119, in check_result
    exceptions.ConflictError.detect(description)
  File "C:\Users\angel\AppData\Local\Programs\Python\Python39\lib\site-packages\aiogram\utils\exceptions.py", line 140, in detect
    raise err(cls.text or description)
aiogram.utils.exceptions.TerminatedByOtherGetUpdates: Terminated by other getupdates request; make sure that only one bot instance is running
2024-04-15 22:54:12,999 ERROR |  390 start_polling: Cause exception while getting updates.
Traceback (most recent call last):
  File "C:\Users\angel\AppData\Local\Programs\Python\Python39\lib\site-packages\aiogram\dispatcher\dispatcher.py", line 381, in start_polling
    updates = await self.bot.get_updates(
  File "C:\Users\angel\AppData\Local\Programs\Python\Python39\lib\site-packages\aiogram\bot\bot.py", line 110, in get_updates
    result = await self.request(api.Methods.GET_UPDATES, payload)
  File "C:\Users\angel\AppData\Local\Programs\Python\Python39\lib\site-packages\aiogram\bot\base.py", line 236, in request
    return await api.make_request(await self.get_session(), self.server, self.__token, method, data, files,
  File "C:\Users\angel\AppData\Local\Programs\Python\Python39\lib\site-packages\aiogram\bot\api.py", line 140, in make_request
    return check_result(method, response.content_type, response.status, await response.text())
  File "C:\Users\angel\AppData\Local\Programs\Python\Python39\lib\site-packages\aiogram\bot\api.py", line 119, in check_result
    exceptions.ConflictError.detect(description)
  File "C:\Users\angel\AppData\Local\Programs\Python\Python39\lib\site-packages\aiogram\utils\exceptions.py", line 140, in detect
    raise err(cls.text or description)
aiogram.utils.exceptions.TerminatedByOtherGetUpdates: Terminated by other getupdates request; make sure that only one bot instance is running
2024-04-15 22:54:23,163 ERROR |  390 start_polling: Cause exception while getting updates.
Traceback (most recent call last):
  File "C:\Users\angel\AppData\Local\Programs\Python\Python39\lib\site-packages\aiogram\dispatcher\dispatcher.py", line 381, in start_polling
    updates = await self.bot.get_updates(
  File "C:\Users\angel\AppData\Local\Programs\Python\Python39\lib\site-packages\aiogram\bot\bot.py", line 110, in get_updates
    result = await self.request(api.Methods.GET_UPDATES, payload)
  File "C:\Users\angel\AppData\Local\Programs\Python\Python39\lib\site-packages\aiogram\bot\base.py", line 236, in request
    return await api.make_request(await self.get_session(), self.server, self.__token, method, data, files,
  File "C:\Users\angel\AppData\Local\Programs\Python\Python39\lib\site-packages\aiogram\bot\api.py", line 140, in make_request
    return check_result(method, response.content_type, response.status, await response.text())
  File "C:\Users\angel\AppData\Local\Programs\Python\Python39\lib\site-packages\aiogram\bot\api.py", line 119, in check_result
    exceptions.ConflictError.detect(description)
  File "C:\Users\angel\AppData\Local\Programs\Python\Python39\lib\site-packages\aiogram\utils\exceptions.py", line 140, in detect
    raise err(cls.text or description)
aiogram.utils.exceptions.TerminatedByOtherGetUpdates: Terminated by other getupdates request; make sure that only one bot instance is running
2024-04-15 22:54:33,304 ERROR |  390 start_polling: Cause exception while getting updates.
Traceback (most recent call last):
  File "C:\Users\angel\AppData\Local\Programs\Python\Python39\lib\site-packages\aiogram\dispatcher\dispatcher.py", line 381, in start_polling
    updates = await self.bot.get_updates(
  File "C:\Users\angel\AppData\Local\Programs\Python\Python39\lib\site-packages\aiogram\bot\bot.py", line 110, in get_updates
    result = await self.request(api.Methods.GET_UPDATES, payload)
  File "C:\Users\angel\AppData\Local\Programs\Python\Python39\lib\site-packages\aiogram\bot\base.py", line 236, in request
    return await api.make_request(await self.get_session(), self.server, self.__token, method, data, files,
  File "C:\Users\angel\AppData\Local\Programs\Python\Python39\lib\site-packages\aiogram\bot\api.py", line 140, in make_request
    return check_result(method, response.content_type, response.status, await response.text())
  File "C:\Users\angel\AppData\Local\Programs\Python\Python39\lib\site-packages\aiogram\bot\api.py", line 119, in check_result
    exceptions.ConflictError.detect(description)
  File "C:\Users\angel\AppData\Local\Programs\Python\Python39\lib\site-packages\aiogram\utils\exceptions.py", line 140, in detect
    raise err(cls.text or description)
aiogram.utils.exceptions.TerminatedByOtherGetUpdates: Terminated by other getupdates request; make sure that only one bot instance is running
2024-04-15 22:54:43,462 ERROR |  390 start_polling: Cause exception while getting updates.
Traceback (most recent call last):
  File "C:\Users\angel\AppData\Local\Programs\Python\Python39\lib\site-packages\aiogram\dispatcher\dispatcher.py", line 381, in start_polling
    updates = await self.bot.get_updates(
  File "C:\Users\angel\AppData\Local\Programs\Python\Python39\lib\site-packages\aiogram\bot\bot.py", line 110, in get_updates
    result = await self.request(api.Methods.GET_UPDATES, payload)
  File "C:\Users\angel\AppData\Local\Programs\Python\Python39\lib\site-packages\aiogram\bot\base.py", line 236, in request
    return await api.make_request(await self.get_session(), self.server, self.__token, method, data, files,
  File "C:\Users\angel\AppData\Local\Programs\Python\Python39\lib\site-packages\aiogram\bot\api.py", line 140, in make_request
    return check_result(method, response.content_type, response.status, await response.text())
  File "C:\Users\angel\AppData\Local\Programs\Python\Python39\lib\site-packages\aiogram\bot\api.py", line 119, in check_result
    exceptions.ConflictError.detect(description)
  File "C:\Users\angel\AppData\Local\Programs\Python\Python39\lib\site-packages\aiogram\utils\exceptions.py", line 140, in detect
    raise err(cls.text or description)
aiogram.utils.exceptions.TerminatedByOtherGetUpdates: Terminated by other getupdates request; make sure that only one bot instance is running
2024-04-15 22:54:53,595 ERROR |  390 start_polling: Cause exception while getting updates.
Traceback (most recent call last):
  File "C:\Users\angel\AppData\Local\Programs\Python\Python39\lib\site-packages\aiogram\dispatcher\dispatcher.py", line 381, in start_polling
    updates = await self.bot.get_updates(
  File "C:\Users\angel\AppData\Local\Programs\Python\Python39\lib\site-packages\aiogram\bot\bot.py", line 110, in get_updates
    result = await self.request(api.Methods.GET_UPDATES, payload)
  File "C:\Users\angel\AppData\Local\Programs\Python\Python39\lib\site-packages\aiogram\bot\base.py", line 236, in request
    return await api.make_request(await self.get_session(), self.server, self.__token, method, data, files,
  File "C:\Users\angel\AppData\Local\Programs\Python\Python39\lib\site-packages\aiogram\bot\api.py", line 140, in make_request
    return check_result(method, response.content_type, response.status, await response.text())
  File "C:\Users\angel\AppData\Local\Programs\Python\Python39\lib\site-packages\aiogram\bot\api.py", line 119, in check_result
    exceptions.ConflictError.detect(description)
  File "C:\Users\angel\AppData\Local\Programs\Python\Python39\lib\site-packages\aiogram\utils\exceptions.py", line 140, in detect
    raise err(cls.text or description)
aiogram.utils.exceptions.TerminatedByOtherGetUpdates: Terminated by other getupdates request; make sure that only one bot instance is running
